Workbook
Name _3__123Graph_ALIQUIDS: '[2]P'!$S$78:$AL$78
Name _6__123Graph_XLIQUIDS: '[2]P'!$R$29:$AK$29
Name _7__123Graph_XR_M_MARG: '[2]P'!$R$29:$AK$29
Name _TBL1: '[6]SENSITIVITY'!$E$9:$K$9
Name _TBL2: '[6]SENSITIVITY'!$E$10:$K$10
Name _TBL3: '[6]SENSITIVITY'!$C$26:$I$32
Name app_lifecycle: '[7]Valuation'!$G$38
Name audience_cov_sens: '[8]Sensitivities'!$G$8
Name avg_commission_increase: '[9]cohorts_all'!$V$3
Name avg_Discount_rate: '[9]cohorts_all'!$V$2
Name bgn: '[10]CAPEX new'!$G$3
Name CAC_sens: '[8]Sensitivities'!$G$6
Name commission_rate: '[7]Valuation'!$G$48
Name Control: '[11]PnL + CFS'!$D$2
Name cpm_price: '[7]Valuation'!$G$47
Name data1: '[12]Data Sheet'!$G$14
Name dead_apps_lifecycle: '[7]Valuation'!$G$28
Name dead_apps_norm_period: '[7]Valuation'!$G$29
Name dead_apps_norm_retention: '[7]Valuation'!$G$30
Name Dead_apps_ret_after_decay: '[7]Valuation'!$G$32
Name dead_apps_start_of_decay: '[7]Valuation'!$G$31
Name delat_12m_retention_increase: '[9]cohorts_all'!$V$4
Name ebitda_margin_sens: '[8]Sensitivities'!$G$5
Name eof: '[13]OUTFLOW'!$A$105
Name eofinflow: '[14]INFLOW'!$A$169
Name exchange: '[10]Capex'!$C$2
Name final_retention: '[7]Valuation'!$G$43
Name FX: '[15]UE'!$C$2
Name headcount_opex_fixed_bus_support: '[16]Assumptions'!$K$156
Name headcount_opex_fixed_eng: '[16]Assumptions'!$K$151
Name headcount_opex_fixed_fiannce: '[16]Assumptions'!$K$150
Name headcount_opex_fixed_management: '[16]Assumptions'!$K$148
Name headcount_opex_fixed_marketing: '[16]Assumptions'!$K$149
Name headcount_opex_fixed_network_management: '[16]Assumptions'!$K$155
Name headcount_opex_fixed_ops: '[16]Assumptions'!$K$152
Name headcount_opex_fixed_service_dev: '[16]Assumptions'!$K$154
Name headcount_opex_fixed_transport_and_switching: '[16]Assumptions'!$K$153
Name headcount_opex_variable_bus_support: '[16]Assumptions'!$L$156
Name headcount_opex_variable_eng: '[16]Assumptions'!$L$151
Name headcount_opex_variable_finance: '[16]Assumptions'!$L$150
Name headcount_opex_variable_management: '[16]Assumptions'!$L$148
Name headcount_opex_variable_marketing: '[16]Assumptions'!$L$149
Name headcount_opex_variable_network_management: '[16]Assumptions'!$L$155
Name headcount_opex_variable_ops: '[16]Assumptions'!$L$152
Name headcount_opex_variable_service_dev: '[16]Assumptions'!$L$154
Name headcount_opex_variable_transport_and_switching: '[16]Assumptions'!$L$153
Name HTML_C: $K$1:$S$107
Name HTML_Control: $K$1:$S$107
Name HTML1_1: '"[ReturnsHistorical]Sheet1'!$A$1:$D$77
Name HTML2_1: '"[histret.xls]Sheet1'!$A$1:$G$85
Name inflation_scenario: '[17]Valuation'!$G$14
Name med_apps_lifecycle: '[7]Valuation'!$G$21
Name med_apps_norm_period: '[7]Valuation'!$G$22
Name Med_apps_norm_retention: '[7]Valuation'!$G$23
Name med_apps_ret_after_decay: '[7]Valuation'!$G$25
Name med_apps_start_of_decay: '[7]Valuation'!$G$24
Name MONOFIRST: '[6]SENSITIVITY'!$B$38
Name norm_period: '[7]Valuation'!$G$39
Name norm_retention: '[7]Valuation'!$G$42
Name old_apps_decay: '[7]Valuation'!$G$41

Sheet Summary
B6: PennyMac Financial Services, Inc. (PFSI) | DCF Model
B7: https://valuesense.io/ticker/pfsi
B8: Date of data download: | E8: 46111.449
B11: Key DCF Assumptions
B13: WACC & Cost of Equity
B15: DCF Model & Sensitivity
B17: KPI Data
B19: Income Statement
B21: Balance Sheet
B23: Cash Flow Statement
B25: Valuation

Sheet Key DCF Assumptions
A3: PennyMac Financial Services, Inc. (PFSI) | Key DCF Assumptions
A5: Metric
A6: Scenario Modelling
A7: Revenue growth
A8: Bull to Base | B8: 1.2
A9: Bear to Base | B9: 0.9
A11: Operating income margin
A12: Bull to Base | B12: 0.02
A13: Bear to Base | B13: -0.01
A15: D&A
A16: Bull to Base | B16: 0
A17: Bear to Base | B17: 0
A19: CAPEX
A20: Bull to Base | B20: 0
A21: Bear to Base | B21: 0
A23: Change in Working Capital
A24: Bull to Base | B24: 0
A25: Bear to Base | B25: 0
A27: Discount rates
A28: WACC | B28: =+'WACC & Cost of Equity'!B25 -> 0.0992
A29: Terminal growth rate (Base case) | B29: 0.02
A31: Terminal Value
A32: Maximum Cap for Dicounted Terminal Value as % of EV | B32: 0.7
A33: Minimum Cap for SUM of Discounted Free Cash Flow to Firm as % of EV | B33: =MAX(1-B32,0%) -> 0.3

Sheet WACC & Cost of Equity
A3: PennyMac Financial Services, Inc. (PFSI) | WACC & Cost of Equity
A5: Metric
A6: Cost of Equity
A7: Risk-free rate | B7: 0.0434
A8: Beta | B8: 1.5
A9: Equity Risk Premium | B9: 0.046
A10: Country Risk premium | B10: 0
A11: Cost of Equity | B11: =+B7+B8*B9+B10 -> 0.114
A13: Cost of Debt
A14: Average Cost of Debt | B14: 0.042709666
A15: Effective Tax Rate | B15: 0.20515606
A16: Cost of Equity | B16: =+B14*(1-B15) -> 0.04
A20: WACC
A21: Cost of Equity | B21: =+B11 -> 0.114
A22: % share of Total Capital | B22: 0.41929916
A23: Cost of Debt (after-tax) | B23: =+B16 -> 0.04
A24: % share of Total Capital | B24: 0.58070084
A25: WACC | B25: =+B21*B22+B23*B24 -> 0.0992

Sheet DCF Model & Sensitivity
A3: PennyMac Financial Services, Inc. (PFSI) | DCF Model & Sensitivity
A5: Key Assumptions & Outputs
A7: Model Scenario (1 - Bull Case, 2 - Base Case, 3 - Bear Case, 4 - Custom) >>> | B7: 2
D8: Sensitivity Toggles:
A9: WACC | B9: =+'Key DCF Assumptions'!B28+'DCF Model & Sensitivity'!F9 -> 0.0992 | D9: WACC | F9: 0
A10: Terminal growth rate (Base case) | B10: =+'Key DCF Assumptions'!B29 -> 0.04 | D10: Terminal growth rate (Base case) | F10: 0
A12: % under/overvalued | B12: =+B78 -> 16.450463
A14: Metric | B14: Dec'21 | C14: Dec'22 | D14: Dec'23 | E14: Dec'24 | F14: Dec'25 | G14: Dec'26 | H14: Dec'27 | I14: Dec'28 | J14: Dec'29 | K14: Dec'30 | L14: Dec'31 | M14: Dec'32 | N14: Dec'33 | O14: Dec'34 | P14: Dec'35 | Q14: Dec'36
B15: Actual | C15: Actual | D15: Actual | E15: Actual | F15: Actual | G15: Estimate | H15: Estimate | I15: Estimate | J15: Estimate | K15: Estimate | L15: Estimate | M15: Estimate | N15: Estimate | O15: Estimate | P15: Estimate | Q15: Terminal
A16: Revenue | B16: 3558.761 | C16: 2321.417 | D16: 2039.121 | E16: 1593.731 | F16: 4363.825 | G16: =+F16*(1+G17) -> 64280.7 | H16: =+G16*(1+H17) -> 70708.77 | I16: =+H16*(1+I17) -> 77779.647 | J16: =+I16*(1+J17) -> 85557.612 | K16: =+J16*(1+K17) -> 94113.373 | L16: =+K16*(1+L17) -> 103524.71 | M16: =+L16*(1+M17) -> 113877.18 | N16: =+M16*(1+N17) -> 125264.9 | ... Q16: =+P16*(1+Q17) -> 157633.35
A17: % growth | C17: =+IFERROR(C16/B16-1,"n/a") -> 0.11294863 | D17: =+IFERROR(D16/C16-1,"n/a") -> 0.15446457 | E17: =+IFERROR(E16/D16-1,"n/a") -> 0.18187864 | F17: =+IFERROR(F16/E16-1,"n/a") -> -0.032820258 | G17: =+CHOOSE($B$7,G18,G19,G20,G21) -> 0.1 | H17: =+CHOOSE($B$7,H18,H19,H20,H21) -> 0.1 | I17: =+CHOOSE($B$7,I18,I19,I20,I21) -> 0.1 | J17: =+CHOOSE($B$7,J18,J19,J20,J21) -> 0.1 | K17: =+CHOOSE($B$7,K18,K19,K20,K21) -> 0.1 | L17: =+CHOOSE($B$7,L18,L19,L20,L21) -> 0.1 | M17: =+CHOOSE($B$7,M18,M19,M20,M21) -> 0.1 | N17: =+CHOOSE($B$7,N18,N19,N20,N21) -> 0.1 | ... P17: =+CHOOSE($B$7,P18,P19,P20,P21) -> 0.1 | Q17: =+CHOOSE($B$7,Q18,Q19,Q20,Q21)+'DCF Model & Sensitivity'!F10 -> 0.04
A18: Bull Case | G18: =+G19*'Key DCF Assumptions'!$B$8 -> 0.12 | H18: =+H19*'Key DCF Assumptions'!$B$8 -> 0.12 | I18: =+I19*'Key DCF Assumptions'!$B$8 -> 0.12 | J18: =+J19*'Key DCF Assumptions'!$B$8 -> 0.12 | K18: =+K19*'Key DCF Assumptions'!$B$8 -> 0.12 | L18: =+L19*'Key DCF Assumptions'!$B$8 -> 0.12 | M18: =+M19*'Key DCF Assumptions'!$B$8 -> 0.12 | N18: =+N19*'Key DCF Assumptions'!$B$8 -> 0.12 | ... Q18: =+Q19*'Key DCF Assumptions'!$B$8 -> 0.048
A19: Base Case | G19: -0.36813974 | H19: 0.12198885 | I19: 0.21104539 | J19: 0.18716472 | K19: 0.16328404 | L19: 0.13940337 | M19: 0.11552269 | N19: 0.091642021 | O19: 0.067761347 | P19: 0.043880674 | Q19: 0.02
A20: Bear Case | G20: =+G19*'Key DCF Assumptions'!$B$9 -> 0.09 | H20: =+H19*'Key DCF Assumptions'!$B$9 -> 0.09 | I20: =+I19*'Key DCF Assumptions'!$B$9 -> 0.09 | J20: =+J19*'Key DCF Assumptions'!$B$9 -> 0.09 | K20: =+K19*'Key DCF Assumptions'!$B$9 -> 0.09 | L20: =+L19*'Key DCF Assumptions'!$B$9 -> 0.09 | M20: =+M19*'Key DCF Assumptions'!$B$9 -> 0.09 | N20: =+N19*'Key DCF Assumptions'!$B$9 -> 0.09 | ... Q20: =+Q19*'Key DCF Assumptions'!$B$9 -> 0.036
A21: Custom | G21: =+G19 -> 0.1 | H21: =+H19 -> 0.1 | I21: =+I19 -> 0.1 | J21: =+J19 -> 0.1 | K21: =+K19 -> 0.1 | L21: =+L19 -> 0.1 | M21: =+M19 -> 0.1 | N21: =+N19 -> 0.1 | ... Q21: =+Q19 -> 0.04
A23: Operating income | B23: 1359.335 | C23: 688.693 | D23: 354.038 | E23: 901.032 | F23: 1511.972 | G23: =+G24*G$16 -> 6428.07 | H23: =+H24*H$16 -> 7070.877 | I23: =+I24*I$16 -> 7777.9647 | J23: =+J24*J$16 -> 8555.7612 | K23: =+K24*K$16 -> 9411.3373 | L23: =+L24*L$16 -> 10352.471 | M23: =+M24*M$16 -> 11387.718 | N23: =+N24*N$16 -> 12526.49 | ... Q23: =+Q24*Q$16 -> 15763.335
A24: % margin | B24: =+IFERROR(B23/B$16,"n/a") -> 1 | C24: =+IFERROR(C23/C$16,"n/a") -> 1 | D24: =+IFERROR(D23/D$16,"n/a") -> 1 | E24: =+IFERROR(E23/E$16,"n/a") -> 1 | F24: =+IFERROR(F23/F$16,"n/a") -> 1 | G24: =+CHOOSE($B$7,G25,G26,G27,G28) -> 0.1 | H24: =+CHOOSE($B$7,H25,H26,H27,H28) -> 0.1 | I24: =+CHOOSE($B$7,I25,I26,I27,I28) -> 0.1 | J24: =+CHOOSE($B$7,J25,J26,J27,J28) -> 0.1 | K24: =+CHOOSE($B$7,K25,K26,K27,K28) -> 0.1 | L24: =+CHOOSE($B$7,L25,L26,L27,L28) -> 0.1 | M24: =+CHOOSE($B$7,M25,M26,M27,M28) -> 0.1 | N24: =+CHOOSE($B$7,N25,N26,N27,N28) -> 0.1 | ... Q24: =+CHOOSE($B$7,Q25,Q26,Q27,Q28) -> 0.1
A25: Bull Case | G25: =+G26+'Key DCF Assumptions'!$B$12 -> 0.12 | H25: =+H26+'Key DCF Assumptions'!$B$12 -> 0.12 | I25: =+I26+'Key DCF Assumptions'!$B$12 -> 0.12 | J25: =+J26+'Key DCF Assumptions'!$B$12 -> 0.12 | K25: =+K26+'Key DCF Assumptions'!$B$12 -> 0.12 | L25: =+L26+'Key DCF Assumptions'!$B$12 -> 0.12 | M25: =+M26+'Key DCF Assumptions'!$B$12 -> 0.12 | N25: =+N26+'Key DCF Assumptions'!$B$12 -> 0.12 | ... Q25: =+Q26+'Key DCF Assumptions'!$B$12 -> 0.12
A26: Base Case | G26: 0.33447142 | H26: 0.33447142 | I26: 0.33447142 | J26: 0.33447142 | K26: 0.33447142 | L26: 0.33447142 | M26: 0.33447142 | N26: 0.33447142 | O26: 0.33447142 | P26: 0.33447142 | Q26: 0.33447142
A27: Bear Case | G27: =+G26+'Key DCF Assumptions'!$B$13 -> 0.09 | H27: =+H26+'Key DCF Assumptions'!$B$13 -> 0.09 | I27: =+I26+'Key DCF Assumptions'!$B$13 -> 0.09 | J27: =+J26+'Key DCF Assumptions'!$B$13 -> 0.09 | K27: =+K26+'Key DCF Assumptions'!$B$13 -> 0.09 | L27: =+L26+'Key DCF Assumptions'!$B$13 -> 0.09 | M27: =+M26+'Key DCF Assumptions'!$B$13 -> 0.09 | N27: =+N26+'Key DCF Assumptions'!$B$13 -> 0.09 | ... Q27: =+Q26+'Key DCF Assumptions'!$B$13 -> 0.09
A28: Custom | G28: =+G26 -> 0.1 | H28: =+H26 -> 0.1 | I28: =+I26 -> 0.1 | J28: =+J26 -> 0.1 | K28: =+K26 -> 0.1 | L28: =+L26 -> 0.1 | M28: =+M26 -> 0.1 | N28: =+N26 -> 0.1 | ... Q28: =+Q26 -> 0.1
A30: NOPAT | B30: =+B23*(1-B31) -> 35013.44 | C30: =+C23*(1-C31) -> 38968.16 | D30: =+D23*(1-D31) -> 44987.36 | E30: =+E23*(1-E31) -> 53169.6 | F30: =+F23*(1-F31) -> 51424.56 | G30: =+G23*(1-G31) -> 5656.7016 | H30: =+H23*(1-H31) -> 6222.3718 | I30: =+I23*(1-I31) -> 6844.6089 | ... Q30: =+Q23*(1-Q31) -> 13871.735
A31: % effective tax rate | B31: 0.26169618 | C31: 0.28521737 | D31: 0.2122463 | E31: 0.22343439 | F31: 0.091292071 | G31: 0.091292071 | H31: 0.091292071 | I31: 0.091292071 | J31: 0.091292071 | K31: 0.091292071 | L31: 0.091292071 | M31: 0.091292071 | N31: 0.091292071 | O31: 0.091292071 | P31: 0.091292071 | Q31: 0.091292071
A32: % margin | B32: =+IFERROR(B30/B$16,"n/a") -> 0.88 | C32: =+IFERROR(C30/C$16,"n/a") -> 0.88 | D32: =+IFERROR(D30/D$16,"n/a") -> 0.88 | E32: =+IFERROR(E30/E$16,"n/a") -> 0.88 | F32: =+IFERROR(F30/F$16,"n/a") -> 0.88 | G32: =+IFERROR(G30/G$16,"n/a") -> 0.088 | H32: =+IFERROR(H30/H$16,"n/a") -> 0.088 | I32: =+IFERROR(I30/I$16,"n/a") -> 0.088 | ... Q32: =+IFERROR(Q30/Q$16,"n/a") -> 0.088
A34: D&A | B34: 42.94 | C34: 50.24 | D34: 70.018 | E34: 69.66 | F34: 0 | G34: =+G35*G$16 -> 1285.614 | H34: =+H35*H$16 -> 1414.1754 | I34: =+I35*I$16 -> 1555.5929 | J34: =+J35*J$16 -> 1711.1522 | K34: =+K35*K$16 -> 1882.2675 | L34: =+L35*L$16 -> 2070.4942 | M34: =+M35*M$16 -> 2277.5436 | N34: =+N35*N$16 -> 2505.298 | ... Q34: =+Q35*Q$16 -> 3152.667
A35: % of revenue | B35: =+IFERROR(B34/B$16,"n/a") -> 0.10993264 | C35: =+IFERROR(C34/C$16,"n/a") -> 0.12788492 | D35: =+IFERROR(D34/D$16,"n/a") -> 0.1180705 | E35: =+IFERROR(E34/E$16,"n/a") -> 0.10150612 | F35: =+IFERROR(F34/F$16,"n/a") -> 0.089874566 | G35: =+CHOOSE($B$7,G36,G37,G38,G39) -> 0.02 | H35: =+CHOOSE($B$7,H36,H37,H38,H39) -> 0.02 | I35: =+CHOOSE($B$7,I36,I37,I38,I39) -> 0.02 | J35: =+CHOOSE($B$7,J36,J37,J38,J39) -> 0.02 | K35: =+CHOOSE($B$7,K36,K37,K38,K39) -> 0.02 | L35: =+CHOOSE($B$7,L36,L37,L38,L39) -> 0.02 | M35: =+CHOOSE($B$7,M36,M37,M38,M39) -> 0.02 | N35: =+CHOOSE($B$7,N36,N37,N38,N39) -> 0.02 | ... Q35: =+CHOOSE($B$7,Q36,Q37,Q38,Q39) -> 0.02
A36: Bull Case | G36: =+G37+'Key DCF Assumptions'!$B$16 -> 0.02 | H36: =+H37+'Key DCF Assumptions'!$B$16 -> 0.02 | I36: =+I37+'Key DCF Assumptions'!$B$16 -> 0.02 | J36: =+J37+'Key DCF Assumptions'!$B$16 -> 0.02 | K36: =+K37+'Key DCF Assumptions'!$B$16 -> 0.02 | L36: =+L37+'Key DCF Assumptions'!$B$16 -> 0.02 | M36: =+M37+'Key DCF Assumptions'!$B$16 -> 0.02 | N36: =+N37+'Key DCF Assumptions'!$B$16 -> 0.02 | ... Q36: =+Q37+'Key DCF Assumptions'!$B$16 -> 0.02
A37: Base Case | G37: 0.026015367 | H37: 0.026015367 | I37: 0.026015367 | J37: 0.026015367 | K37: 0.026015367 | L37: 0.026015367 | M37: 0.026015367 | N37: 0.026015367 | O37: 0.026015367 | P37: 0.026015367 | Q37: 0.026015367
A38: Bear Case | G38: =+G37+'Key DCF Assumptions'!$B$17 -> 0.02 | H38: =+H37+'Key DCF Assumptions'!$B$17 -> 0.02 | I38: =+I37+'Key DCF Assumptions'!$B$17 -> 0.02 | J38: =+J37+'Key DCF Assumptions'!$B$17 -> 0.02 | K38: =+K37+'Key DCF Assumptions'!$B$17 -> 0.02 | L38: =+L37+'Key DCF Assumptions'!$B$17 -> 0.02 | M38: =+M37+'Key DCF Assumptions'!$B$17 -> 0.02 | N38: =+N37+'Key DCF Assumptions'!$B$17 -> 0.02 | ... Q38: =+Q37+'Key DCF Assumptions'!$B$17 -> 0.02
A39: Custom | G39: =+G37 -> 0.02 | H39: =+H37 -> 0.02 | I39: =+I37 -> 0.02 | J39: =+J37 -> 0.02 | K39: =+K37 -> 0.02 | L39: =+L37 -> 0.02 | M39: =+M37 -> 0.02 | N39: =+N37 -> 0.02 | ... Q39: =+Q37 -> 0.02
A41: CAPEX | B41: -56.879 | C41: -83.087 | D41: -36.17 | E41: -22.097 | F41: 0 | G41: =+G42*G$16 -> 1285.614 | H41: =+H42*H$16 -> 1414.1754 | I41: =+I42*I$16 -> 1555.5929 | J41: =+J42*J$16 -> 1711.1522 | K41: =+K42*K$16 -> 1882.2675 | L41: =+L42*L$16 -> 2070.4942 | M41: =+M42*M$16 -> 2277.5436 | N41: =+N42*N$16 -> 2505.298 | ... Q41: =+Q42*Q$16 -> 3152.667
A42: % of revenue | B42: =+IFERROR(B41/B$16,"n/a") -> 0.10993264 | C42: =+IFERROR(C41/C$16,"n/a") -> 0.12788492 | D42: =+IFERROR(D41/D$16,"n/a") -> 0.1180705 | E42: =+IFERROR(E41/E$16,"n/a") -> 0.10150612 | F42: =+IFERROR(F41/F$16,"n/a") -> 0.089874566 | G42: =+CHOOSE($B$7,G43,G44,G45,G46) -> 0.02 | H42: =+CHOOSE($B$7,H43,H44,H45,H46) -> 0.02 | I42: =+CHOOSE($B$7,I43,I44,I45,I46) -> 0.02 | J42: =+CHOOSE($B$7,J43,J44,J45,J46) -> 0.02 | K42: =+CHOOSE($B$7,K43,K44,K45,K46) -> 0.02 | L42: =+CHOOSE($B$7,L43,L44,L45,L46) -> 0.02 | M42: =+CHOOSE($B$7,M43,M44,M45,M46) -> 0.02 | N42: =+CHOOSE($B$7,N43,N44,N45,N46) -> 0.02 | ... Q42: =+CHOOSE($B$7,Q43,Q44,Q45,Q46) -> 0.02
A43: Bull Case | G43: =+G44+'Key DCF Assumptions'!$B$20 -> 0.02 | H43: =+H44+'Key DCF Assumptions'!$B$20 -> 0.02 | I43: =+I44+'Key DCF Assumptions'!$B$20 -> 0.02 | J43: =+J44+'Key DCF Assumptions'!$B$20 -> 0.02 | K43: =+K44+'Key DCF Assumptions'!$B$20 -> 0.02 | L43: =+L44+'Key DCF Assumptions'!$B$20 -> 0.02 | M43: =+M44+'Key DCF Assumptions'!$B$20 -> 0.02 | N43: =+N44+'Key DCF Assumptions'!$B$20 -> 0.02 | ... Q43: =+Q44+'Key DCF Assumptions'!$B$20 -> 0.02
A44: Base Case | G44: -0.010534328 | H44: -0.010534328 | I44: -0.010534328 | J44: -0.010534328 | K44: -0.010534328 | L44: -0.010534328 | M44: -0.010534328 | N44: -0.010534328 | O44: -0.010534328 | P44: -0.010534328 | Q44: -0.010534328
A45: Bear Case | G45: =+G44+'Key DCF Assumptions'!$B$21 -> 0.02 | H45: =+H44+'Key DCF Assumptions'!$B$21 -> 0.02 | I45: =+I44+'Key DCF Assumptions'!$B$21 -> 0.02 | J45: =+J44+'Key DCF Assumptions'!$B$21 -> 0.02 | K45: =+K44+'Key DCF Assumptions'!$B$21 -> 0.02 | L45: =+L44+'Key DCF Assumptions'!$B$21 -> 0.02 | M45: =+M44+'Key DCF Assumptions'!$B$21 -> 0.02 | N45: =+N44+'Key DCF Assumptions'!$B$21 -> 0.02 | ... Q45: =+Q44+'Key DCF Assumptions'!$B$21 -> 0.02
A46: Custom | G46: =+G44 -> 0.02 | H46: =+H44 -> 0.02 | I46: =+I44 -> 0.02 | J46: =+J44 -> 0.02 | K46: =+K44 -> 0.02 | L46: =+L44 -> 0.02 | M46: =+M44 -> 0.02 | N46: =+N44 -> 0.02 | ... Q46: =+Q44 -> 0.02
A48: Change in Working Capital | B48: -17.993 | C48: 309.523 | D48: 11.24 | E48: -209.538 | F48: 0 | G48: =+G49*G$16 -> 1285.614 | H48: =+H49*H$16 -> 1414.1754 | I48: =+I49*I$16 -> 1555.5929 | J48: =+J49*J$16 -> 1711.1522 | K48: =+K49*K$16 -> 1882.2675 | L48: =+L49*L$16 -> 2070.4942 | M48: =+M49*M$16 -> 2277.5436 | N48: =+N49*N$16 -> 2505.298 | ... Q48: =+Q49*Q$16 -> 3152.667
A49: % of revenue | B49: =+IFERROR(B48/B$16,"n/a") -> 0.10993264 | C49: =+IFERROR(C48/C$16,"n/a") -> 0.12788492 | D49: =+IFERROR(D48/D$16,"n/a") -> 0.1180705 | E49: =+IFERROR(E48/E$16,"n/a") -> 0.10150612 | F49: =+IFERROR(F48/F$16,"n/a") -> 0.089874566 | G49: =+CHOOSE($B$7,G50,G51,G52,G53) -> 0.02 | H49: =+CHOOSE($B$7,H50,H51,H52,H53) -> 0.02 | I49: =+CHOOSE($B$7,I50,I51,I52,I53) -> 0.02 | J49: =+CHOOSE($B$7,J50,J51,J52,J53) -> 0.02 | K49: =+CHOOSE($B$7,K50,K51,K52,K53) -> 0.02 | L49: =+CHOOSE($B$7,L50,L51,L52,L53) -> 0.02 | M49: =+CHOOSE($B$7,M50,M51,M52,M53) -> 0.02 | N49: =+CHOOSE($B$7,N50,N51,N52,N53) -> 0.02 | ... Q49: =+CHOOSE($B$7,Q50,Q51,Q52,Q53) -> 0.02
A50: Bull Case | G50: =+G51+'Key DCF Assumptions'!$B$24 -> 0.02 | H50: =+H51+'Key DCF Assumptions'!$B$24 -> 0.02 | I50: =+I51+'Key DCF Assumptions'!$B$24 -> 0.02 | J50: =+J51+'Key DCF Assumptions'!$B$24 -> 0.02 | K50: =+K51+'Key DCF Assumptions'!$B$24 -> 0.02 | L50: =+L51+'Key DCF Assumptions'!$B$24 -> 0.02 | M50: =+M51+'Key DCF Assumptions'!$B$24 -> 0.02 | N50: =+N51+'Key DCF Assumptions'!$B$24 -> 0.02 | ... Q50: =+Q51+'Key DCF Assumptions'!$B$24 -> 0.02
A51: Base Case | G51: -0.041988071 | H51: -0.041988071 | I51: -0.041988071 | J51: -0.041988071 | K51: -0.041988071 | L51: -0.041988071 | M51: -0.041988071 | N51: -0.041988071 | O51: -0.041988071 | P51: -0.041988071 | Q51: -0.041988071
...

Sheet KPI Data
A3: PennyMac Financial Services, Inc. (PFSI) | KPI Data
A5: Metric | B5: Jun'16

Sheet Income Statement
A3: PennyMac Financial Services, Inc. (PFSI) | Income Statement
A5: Metric | B5: Dec'10 | C5: Dec'11 | D5: Dec'12 | E5: Dec'13 | F5: Dec'14 | G5: Dec'15 | H5: Dec'16 | I5: Dec'17 | J5: Dec'18 | K5: Dec'19 | L5: Dec'20 | M5: Dec'21 | N5: Dec'22 | O5: Dec'23 | P5: Dec'24 | Q5: Dec'25
A6: Revenue | B6: 69.229 | C6: 76.659 | D6: 272.965 | E6: 405.614 | F6: 526.877 | G6: 778.067 | H6: 1013.946 | I6: 1080.515 | J6: 1137.394 | K6: 1679.711 | L6: 3952.631 | M6: 3558.761 | N6: 2321.417 | O6: 2039.121 | P6: 1593.731 | Q6: 4363.825
A7: % growth | C7: 0.10732496 | D7: 2.5607691 | E7: 0.48595607 | F7: 0.29896157 | G7: 0.47675264 | H7: 0.30316027 | I7: 0.065653398 | J7: 0.052640639 | K7: 0.47680663 | L7: 1.3531613 | M7: -0.099647551 | N7: -0.34768955 | O7: -0.12160504 | P7: -0.21842255 | Q7: 1.7381189
A8: Cost of Goods Sold (COGS) | B8: 28.519 | C8: 34.532 | D8: 75.774 | E8: 134.708 | F8: 213.669 | G8: 320.184 | H8: 425.829 | I8: 512.355 | J8: 565.849 | K8: 788.001 | L8: 1185.388 | M8: 1425.51 | N8: 1014.456 | O8: 1191.655 | P8: 37.992 | Q8: 374.616
A9: Gross Profit | B9: 40.71 | C9: 42.127 | D9: 197.191 | E9: 270.906 | F9: 313.208 | G9: 457.883 | H9: 588.117 | I9: 568.16 | J9: 571.545 | K9: 891.71 | L9: 2767.243 | M9: 2133.251 | N9: 1306.961 | O9: 847.466 | P9: 1555.739 | Q9: 3989.209
A10: % margin | B10: 0.58804836 | C10: 0.54953756 | D10: 0.72240397 | E10: 0.66789115 | F10: 0.59446133 | G10: 0.58848788 | H10: 0.58002793 | I10: 0.52582333 | J10: 0.50250397 | K10: 0.53087108 | L10: 0.70010153 | M10: 0.59943643 | N10: 0.56300139 | O10: 0.41560359 | P10: 0.9761616 | Q10: 0.91415421
A12: Operating Expenses | B12: 7.668 | C12: 27.428 | D12: 78.868 | E12: 88.78 | F12: 90.175 | G12: 178.69 | H12: 205.034 | I12: 232.251 | J12: 303.848 | K12: 362.266 | L12: 526.447 | M12: 773.916 | N12: 618.268 | O12: 493.428 | P12: 654.707 | Q12: 2477.237
A13: Research & Development Expenses (R&D) | B13: 0 | C13: 0 | D13: 0 | E13: 0 | F13: 0 | G13: 0 | H13: 0 | I13: 0 | J13: 0 | K13: 0 | L13: 0 | M13: 0 | N13: 0 | O13: 0 | P13: 149.547 | Q13: 0
A14: Selling, General & Administrative Expenses (SG&A) | B14: 3.182 | C14: 19.877 | D14: 59.257 | E14: 41.958 | F14: 63.376 | G14: 107.93 | H14: 135.228 | I14: 127.079 | J14: 150.592 | K14: 215.914 | L14: 322.507 | M14: 461.244 | N14: 338.169 | O14: 238.082 | P14: 654.707 | Q14: 829.056
A15: Operating Income | B15: 33.042 | C15: 14.699 | D15: 118.323 | E15: 182.126 | F15: 223.033 | G15: 279.193 | H15: 383.083 | I15: 335.909 | J15: 267.697 | K15: 529.444 | L15: 2240.796 | M15: 1359.335 | N15: 688.693 | O15: 354.038 | P15: 901.032 | Q15: 1511.972
A16: % margin | B16: 0.47728553 | C16: 0.19174526 | D16: 0.43347316 | E16: 0.4490131 | F16: 0.42331132 | G16: 0.358829 | H16: 0.37781401 | I16: 0.31087861 | J16: 0.23535995 | K16: 0.31519946 | L16: 0.56691252 | M16: 0.38196861 | N16: 0.29666923 | O16: 0.17362285 | P16: 0.56536015 | Q16: 0.34647861
A17: Interest Income | B17: 0 | C17: 1.532 | D17: 0 | E17: 15.632 | F17: 27.771 | G17: 49.155 | H17: 0 | I17: 143.179 | J17: 0 | K17: 0 | L17: 0 | M17: 0 | N17: 0 | O17: 0 | P17: 793.566 | Q17: 924.447
A18: Interest Expense | B18: 0.79 | C18: 1.875 | D18: 7.879 | E18: 16.673 | F18: 37.257 | G18: 68.537 | H18: 106.206 | I18: 144.52 | J18: 144.597 | K18: 0 | L18: 0 | M18: 0 | N18: 0 | O18: 0 | P18: 819.348 | Q18: 960.555
A19: Pre-tax Income | B19: 33.042 | C19: 14.699 | D19: 118.323 | E19: 182.126 | F19: 223.033 | G19: 279.193 | H19: 383.083 | I19: 335.909 | J19: 267.697 | K19: 529.444 | L19: 2240.609 | M19: 1359.183 | N19: 665.247 | O19: 183.631 | P19: 401.026 | Q19: 551.417
A20: Income Tax | B20: 0 | C20: 0 | D20: 0 | E20: 9.961 | F20: 26.722 | G20: 31.635 | H20: 46.103 | I20: 24.387 | J20: 23.254 | K20: 136.479 | L20: 593.725 | M20: 355.693 | N20: 189.74 | O20: 38.975 | P20: 89.603 | Q20: 50.34
... A27: % margin | B27: 0.48583686 | C27: 0.31813616 | D27: 0.48026304 | E27: 0.52365303 | F27: 0.50467187 | G27: 0.55875008 | H27: 0.67972752 | I27: 0.57152562 | J27: 0.24672365 | K27: 0.33018954 | L27: 0.5764907 | M27: 0.39403461 | N27: 0.31831119 | O27: 0.20796019 | P27: 0.29689264 | Q27: 0.34647861

Sheet Balance Sheet
A3: PennyMac Financial Services, Inc. (PFSI) | Balance Sheet
A5: Metric | B5: Dec'10 | C5: Dec'11 | D5: Dec'12 | E5: Dec'13 | F5: Dec'14 | G5: Dec'15 | H5: Dec'16 | I5: Dec'17 | J5: Dec'18 | K5: Dec'19 | L5: Dec'20 | M5: Dec'21 | N5: Dec'22 | O5: Dec'23 | P5: Dec'24 | Q5: Dec'25
A6: Total Assets | B6: 0 | C6: 289.281 | D6: 832.163 | E6: 1584.475 | F6: 2507.125 | G6: 3505.294 | H6: 5133.902 | I6: 7368.093 | J6: 7478.573 | K6: 10204.017 | L6: 31597.795 | M6: 18776.612 | N6: 16822.584 | O6: 18844.563 | P6: 26086.887 | Q6: 29388.689
A7: Current Assets | B7: 0 | C7: 243.042 | D7: 675.109 | E7: 987.909 | F7: 1640.456 | G7: 1958.626 | H7: 3327.261 | I7: 5013.385 | J7: 4244.261 | K7: 6685.828 | L7: 27834.902 | M7: 14207.101 | N7: 10472.603 | O7: 11272.894 | P7: 16117.025 | Q7: 301.68
A8: % of total assets | C8: 0.84015888 | D8: 0.81127015 | E8: 0.62349296 | F8: 0.65431759 | G8: 0.55876226 | H8: 0.64809593 | I8: 0.68041826 | J8: 0.56752284 | K8: 0.65521529 | L8: 0.8809128 | M8: 0.75663815 | N8: 0.62253236 | O8: 0.59820405 | P8: 0.61782094 | Q8: 0.010265174
A9: Cash & Cash Equivalents | B9: 0 | C9: 16.465 | D9: 12.323 | E9: 30.639 | F9: 76.256 | G9: 105.472 | H9: 99.367 | I9: 37.725 | J9: 155.289 | K9: 135.692 | L9: 532.716 | M9: 340.069 | N9: 1328.536 | O9: 938.371 | P9: 238.482 | Q9: 301.68
A10: Short-Term Investments | B10: 0 | C10: 16.041 | D10: 53.164 | E10: 142.582 | F10: 21.687 | G10: 46.319 | H10: 85.964 | I10: 170.08 | J10: 117.824 | K10: 74.611 | L10: 15.217 | M10: 6.873 | N10: 12.194 | O10: 10.268 | P10: 420.553 | Q10: 410.037
A11: Accounts Receivables | B11: 0 | C11: 57.114 | D11: 68.086 | E11: 129.356 | F11: 165.999 | G11: 406.277 | H11: 470.809 | I11: 1235.314 | J11: 164.489 | K11: 6007.639 | L11: 26383.531 | M11: 12955.961 | N11: 8328.095 | O11: 9442.875 | P11: 14538.866 | Q11: 17.122
A12: Inventory | B12: 0 | C12: 0 | D12: 0 | E12: 0 | F12: 0 | G12: -93.757 | H12: -91.788 | I12: -20.765 | J12: 1102.84 | K12: 0 | L12: 0 | M12: 0 | N12: 0 | O12: 0 | P12: 0 | Q12: 0
A13: Other Current Assets | B13: 0 | C13: 153.422 | D13: 541.536 | E13: 685.332 | F13: 1376.514 | G13: 1494.315 | H13: 2762.909 | I13: 3591.031 | J13: 2703.819 | K13: 467.886 | L13: 903.438 | M13: 904.198 | N13: 803.778 | O13: 881.38 | P13: 919.124 | Q13: -427.159
A14: Non-Current Assets | B14: 0 | C14: 46.239 | D14: 157.054 | E14: 596.566 | F14: 866.669 | G14: 1546.668 | H14: 1806.641 | I14: 2354.708 | J14: 3234.312 | K14: 3518.189 | L14: 3762.893 | M14: 4569.511 | N14: 6349.981 | O14: 7571.669 | P14: 9969.862 | Q14: 29087.009
A15: % of total assets | C15: 0.15984112 | D15: 0.18872985 | E15: 0.37650704 | F15: 0.34568241 | G15: 0.44123774 | H15: 0.35190407 | I15: 0.31958174 | J15: 0.43247716 | K15: 0.34478471 | L15: 0.1190872 | M15: 0.24336185 | N15: 0.37746764 | O15: 0.40179595 | P15: 0.38217906 | Q15: 0.98973483
A16: Property, Plant & Equipment (PPE) | B16: 0 | C16: 2.541 | D16: 5.065 | E16: 9.837 | F16: 11.339 | G16: 16.311 | H16: 31.321 | I16: 29.453 | J16: 33.374 | K16: 103.57 | L16: 107.151 | M16: 120.717 | N16: 94.248 | O16: 68.942 | P16: 49.488 | Q16: 0
A17: Goodwill & Intangible Assets | B17: 0 | C17: 32.68 | D17: 109.77 | E17: 484.428 | F17: 731.395 | G17: 1414.96 | H17: 1638.877 | I17: 2145.317 | J17: 2860.36 | K17: 2989.92 | L17: 2662.608 | M17: 3987.558 | N17: 6111.081 | O17: 7248.084 | P17: 8865.33 | Q17: 9598.941
A18: Long-Term Investments | B18: 0 | C18: 1.247 | D18: 1.897 | E18: 1.722 | F18: 1.582 | G18: 1.145 | H18: 1.228 | I18: 1.205 | J18: 1.397 | K18: 1.672 | L18: 1.105 | M18: 1.3 | N18: 0.929 | O18: 1.121 | P18: 0.944 | Q18: 0
A19: Tax Assets | B19: 0 | C19: 5.46 | D19: 27.29 | E19: 63.117 | F19: 46.038 | G19: 18.378 | H19: 84.323 | I19: 80.626 | J19: 98.597 | K19: 0 | L19: 0 | M19: 0 | N19: 0 | O19: 0 | P19: 0 | Q19: 0
A20: Other Non-current Assets | B20: 0 | C20: 4.311 | D20: 13.032 | E20: 37.462 | F20: 76.315 | G20: 95.874 | H20: 50.892 | I20: 98.107 | J20: 240.584 | K20: 423.027 | L20: 992.029 | M20: 459.936 | N20: 143.723 | O20: 253.522 | P20: 1054.1 | Q20: 19488.068
A22: Total Liabilities | B22: 0 | C22: 165.366 | D22: 570.413 | E22: 955.271 | F22: 1699.859 | G22: 2442.944 | H22: 3734.546 | I22: 5648.419 | J22: 5824.782 | K22: 8142.51 | L22: 28208.407 | M22: 15358.287 | N22: 13351.535 | O22: 15305.96 | P22: 22257.236 | Q22: 25079.713
A23: Current Liabilities | B23: 0 | C23: 68.615 | D23: 119.853 | E23: 374.277 | F23: 488.128 | G23: 1936.193 | H23: 2449.865 | I23: 2960.384 | J23: 2857.895 | K23: 5118.919 | L23: 10893.116 | M23: 8595.959 | N23: 4583.045 | O23: 5491.047 | P23: 10318.836 | Q23: 7341.783
A24: % of total liabilities | C24: 0.4149281 | D24: 0.21011618 | E24: 0.39180191 | F24: 0.28715793 | G24: 0.79256545 | H24: 0.65600076 | I24: 0.52410843 | J24: 0.49064411 | K24: 0.62866598 | L24: 0.38616559 | M24: 0.55969517 | N24: 0.34325978 | O24: 0.35875221 | P24: 0.46361714 | Q24: 0.29273792
A25: Accounts Payables | B25: 0 | C25: 38.993 | D25: 83.058 | E25: 266.284 | F25: 377.196 | G25: 664.719 | H25: 593.316 | I25: 482.675 | J25: 476.953 | K25: 427.139 | L25: 580.454 | M25: 587.432 | N25: 552.919 | O25: 658.106 | P25: 476.731 | Q25: 0
A26: Short-Term Debt | B26: 0 | C26: 77.7 | D26: 393.534 | E26: 471.592 | F26: 0 | G26: 1166.731 | H26: 1735.114 | I26: 2381.538 | J26: 1933.859 | K26: 4141.053 | L26: 9654.797 | M26: 7292.735 | N26: 3001.283 | O26: 3763.956 | P26: 8685.207 | Q26: 16203.802
B27: 0 | C27: 0 | D27: 0 | E27: 0 | F27: 0 | G27: 0 | H27: 0 | I27: 0 | J27: 0 | K27: 0 | L27: 0 | M27: 0 | N27: 0 | O27: 0 | P27: 0 | Q27: 0
A28: Other Current Liabilities | B28: 0 | C28: -48.078 | D28: -356.739 | E28: -363.599 | F28: 110.932 | G28: 104.743 | H28: 96.347 | I28: 44.011 | J28: 46.537 | K28: 46.158 | L28: 35.165 | M28: 30.53 | N28: 26.099 | O28: 26.099 | P28: 25.898 | Q28: -8862.019
A29: Non-Current Liabilities | B29: 0 | C29: 96.751 | D29: 450.56 | E29: 580.994 | F29: 1211.731 | G29: 506.751 | H29: 1284.681 | I29: 2688.035 | J29: 2966.887 | K29: 3023.591 | L29: 17315.291 | M29: 6762.328 | N29: 8768.49 | O29: 9814.913 | P29: 11938.4 | Q29: 17737.93
A30: % of total liabilities | C30: 0.5850719 | D30: 0.78988382 | E30: 0.60819809 | F30: 0.71284207 | G30: 0.20743455 | H30: 0.34399924 | I30: 0.47589157 | J30: 0.50935589 | K30: 0.37133402 | L30: 0.61383441 | M30: 0.44030483 | N30: 0.65674022 | O30: 0.64124779 | P30: 0.53638286 | Q30: 0.70726208
A31: Long-Term Debt | B31: 0 | C31: 96.302 | D31: 0 | E31: 570.409 | F31: 1191.959 | G31: 477.056 | H31: 1243.252 | I31: 2662.186 | J31: 2942.668 | K31: 2979.815 | L31: 17239.965 | M31: 6696.201 | N31: 8799.907 | O31: 9730.85 | P31: 11868.371 | Q31: 6157.763
A32: Other Non-Current Liabilities | B32: 0 | C32: 0.449 | D32: 450.56 | E32: 10.585 | F32: 19.772 | G32: 29.695 | H32: -3706.365 | I32: -5629.932 | J32: 24.219 | K32: 43.776 | L32: 75.326 | M32: 66.127 | N32: -31.417 | O32: 84.063 | P32: 70.029 | Q32: 11580.167
A34: Total Equity | B34: 0 | C34: 123.915 | D34: 261.75 | E34: 629.204 | F34: 807.266 | G34: 1062.35 | H34: 1399.356 | I34: 1719.674 | J34: 1653.791 | K34: 2061.507 | L34: 3389.388 | M34: 3418.325 | N34: 3471.049 | O34: 3538.603 | P34: 3829.651 | Q34: 4308.976
A35: Common Stock | B35: 0 | C35: 0 | D35: 261.75 | E35: 0.002 | F35: 0.002 | G35: 0.002 | H35: 0.002 | I35: 0.002 | J35: 0.008 | K35: 0.008 | L35: 0.007 | M35: 0.006 | N35: 0.005 | O35: 0.005 | P35: 0.005 | Q35: 0.005
A36: Retained Earnings | B36: 0 | C36: 44.722 | D36: 147.174 | E36: 14.4 | F36: 51.242 | G36: 98.47 | H36: 164.549 | I36: 265.306 | J36: 343.135 | K36: 726.392 | L36: 2342.329 | M36: 3292.923 | N36: 3471.044 | O36: 3514.311 | P36: 3773.574 | Q36: 4212.101
A37: Preferred Stock | B37: 0 | C37: 96.374 | D37: 97.148 | E37: 0 | F37: 0 | G37: 0 | H37: 164.549 | I37: 265.306 | J37: 343.135 | K37: 0 | L37: 0 | M37: 0 | N37: 0 | O37: 0 | P37: 0 | Q37: 0
A38: Minority Investment | B38: 0 | C38: 0 | D38: 0 | E38: 461.802 | F38: 593.302 | G38: 791.524 | H38: 1052.033 | I38: 1250.263 | J38: 14.211 | K38: 0 | L38: 0 | M38: 0 | N38: 0 | O38: 0 | P38: 0 | Q38: 0
A39: Accumulated Other Income & Loss | B39: 0 | C39: 0 | D39: -261.75 | E39: 0 | F39: 0 | G39: 0 | H39: 1399.356 | I39: 1719.674 | J39: 1653.791 | K39: 0 | L39: 0 | M39: 0 | N39: 0 | O39: 0 | P39: 0 | Q39: 0
A40: Other Equity | B40: 0 | C40: -17.181 | D40: 17.428 | E40: 153 | F40: 162.72 | G40: 172.354 | H40: -1381.133 | I40: -1780.877 | J40: -700.489 | K40: 1335.107 | L40: 1047.052 | M40: 125.396 | N40: 0 | O40: 24.287 | P40: 56.072 | Q40: 96.870001
A42: Total Liabilities & Equity | B42: 0 | C42: 289.281 | D42: 832.163 | E42: 1584.475 | F42: 2507.125 | G42: 3505.294 | H42: 5133.902 | I42: 7368.093 | J42: 7478.573 | K42: 10204.017 | L42: 31597.795 | M42: 18776.612 | N42: 16822.584 | O42: 18844.563 | P42: 26086.887 | Q42: 29388.689

Sheet Cash Flow Statement
A3: PennyMac Financial Services, Inc. (PFSI) | Cash Flow Statement
A5: Metric | B5: Dec'10 | C5: Dec'11 | D5: Dec'12 | E5: Dec'13 | F5: Dec'14 | G5: Dec'15 | H5: Dec'16 | I5: Dec'17 | J5: Dec'18 | K5: Dec'19 | L5: Dec'20 | M5: Dec'21 | N5: Dec'22 | O5: Dec'23 | P5: Dec'24 | Q5: Dec'25
A6: Cash Flow from Operating Activities | B6: -12.647 | C6: -74.718 | D6: -308.057 | E6: -98.39 | F6: -578.954 | G6: 53.144 | H6: -938.522 | I6: -883.585 | J6: 572.396 | K6: -2147.002 | L6: -6198.938 | M6: 2563.061 | N6: 6033.235 | O6: -1582.219 | P6: -4533.27 | Q6: 0
A7: Net Income | B7: 33.042 | C7: 14.699 | D7: 118.323 | E7: 172.165 | F7: 196.311 | G7: 247.558 | H7: 336.98 | I7: 311.522 | J7: 244.443 | K7: 392.965 | L7: 1646.884 | M7: 1003.49 | N7: 475.507 | O7: 144.656 | P7: 311.423 | Q7: 501.077
A8: Depreciation & Amortization (D&A) | B8: 0.592 | C8: 9.689 | D8: 12.772 | E8: 30.275 | F8: 42.867 | G8: 155.552 | H8: 306.124 | I8: 281.633 | J8: 258.814 | K8: 25.179 | L8: 37.859 | M8: 42.94 | N8: 50.24 | O8: 70.018 | P8: 69.66 | Q8: 0
A9: Deferred Income Tax | B9: -0.073 | C9: 0.114 | D9: -0.65 | E9: 0.197 | F9: 18.826 | G9: 30.219 | H9: 35.502 | I9: 105.828 | J9: 39.525 | K9: 0 | L9: -779.606 | M9: 425.877 | N9: 0 | O9: 0 | P9: 0 | Q9: 0
A10: Stock-based Compensation | B10: 1.292 | C10: 1.116 | D10: 20.308 | E10: 3.937 | F10: 10.331 | G10: 17.521 | H10: 16.198 | I10: 20.697 | J10: 25.251 | K10: 0 | L10: 45.105 | M10: 37.794 | N10: 42.552 | O10: 27.582 | P10: 20.868 | Q10: 0
A11: Other Non Cash Items | B11: -40.533 | C11: -97.242 | D11: -472.845 | E11: -282.509 | F11: -795.642 | G11: -374.624 | H11: -1603.681 | I11: -1467.167 | J11: 31.65 | K11: -2575.589 | L11: -6653.041 | M11: 1070.953 | N11: 5155.413 | O11: -1835.715 | P11: -4725.683 | Q11: -501.077
A12: Change in Working Capital | B12: -6.967 | C12: -3.094 | D12: 14.035 | E12: -22.455 | F12: -51.647 | G12: -23.082 | H12: -29.645 | I12: -136.098 | J12: -27.287 | K12: 10.443 | L12: -496.139 | M12: -17.993 | N12: 309.523 | O12: 11.24 | P12: -209.538 | Q12: 0
A14: Cash Flow from Investing Activities | B14: -7.176 | C14: -12.389 | D14: -45.535 | E14: -284.781 | F14: 6.752 | G14: -563.142 | H14: -34.739 | I14: -339.231 | J14: -322.611 | K14: 50.661 | L14: 783.034 | M14: -304.369 | N14: -721.582 | O14: -273.288 | P14: -1887.955 | Q14: 0
A15: Capital Expenditure | B15: -12.806 | C15: -3.352 | D15: -3.873 | E15: -202.829 | F15: -140.216 | G15: -394.728 | H15: -30.535 | I15: -202.314 | J15: -258.529 | K15: -6.124 | L15: -84.234 | M15: -56.879 | N15: -83.087 | O15: -36.17 | P15: -22.097 | Q15: 0
A16: Acquisitions Net | B16: 0 | C16: 0 | D16: 0 | E16: 0 | F16: 0 | G16: -385.606 | H16: 0 | I16: 0 | J16: 245.108 | K16: 0 | L16: 131.84 | M16: -48.98 | N16: 0 | O16: 0 | P16: 0 | Q16: 0
A17: Purchases of Investments | B17: 0 | C17: 0 | D17: 0 | E17: 0 | F17: 0 | G17: -24.632 | H17: -66.96 | I17: -120.734 | J17: -122.227 | K17: -21.127 | L17: -131.84 | M17: -434.397 | N17: -877.199 | O17: -96.459 | P17: -2048.234 | Q17: 0
A18: Sales Maturities of Investments | B18: 0 | C18: 0 | D18: 0 | E18: 0 | F18: 139.515 | G18: 2.033 | H18: 0 | I18: 0 | J18: 52.256 | K18: 43.213 | L18: 972.458 | M18: 8.344 | N18: 0 | O18: 1.926 | P18: 298.702 | Q18: 0
... A34: % margin | B34: -0.36766384 | C34: -1.0184062 | D34: -1.1427472 | E34: -0.74262476 | F34: -1.3649675 | G34: -0.43901618 | H34: -0.95572841 | I34: -1.0049828 | J34: 0.27595275 | K34: -1.2818431 | L34: -1.5896176 | M34: 0.7042288 | N34: 2.5631535 | O34: -0.79366992 | P34: -2.8583036 | Q34: 0

Sheet Valuation
A3: PennyMac Financial Services, Inc. (PFSI) | Valuation
A5: Metric | B5: Dec'13 | C5: Dec'14 | D5: Dec'15 | E5: Dec'16 | F5: Dec'17 | G5: Dec'18 | H5: Dec'19 | I5: Dec'20 | J5: Dec'21 | K5: Dec'22 | L5: Dec'23 | M5: Dec'24 | N5: Dec'25
A6: EV & Equity Value
A7: Market Cap | B7: 309.17446 | C7: 373.44417 | D7: 342.04632 | E7: 371.94435 | F7: 521.9619 | G7: 1246.6183 | H7: 2623.903 | I7: 4677.3139 | J7: 4110.4908 | K7: 2842.2922 | L7: 4417.3512 | M7: 5198.1581 | N7: 6892.8735
A8: Enterprise Value | B8: 957.83046 | C8: 2478.9192 | D8: 3605.2663 | E8: 3834.9303 | F8: 4462.0319 | G8: 5463.4013 | H8: 8702.077 | I8: 30949.297 | J8: 18620.275 | K8: 12527.415 | L8: 17118.566 | M8: 16441.805 | N8: 25611.718
A9: Net Debt | B9: 868.78 | C9: 1094.016 | D9: 1491.996 | E9: 2793.035 | F9: 4835.919 | G9: 4603.414 | H9: 6910.565 | I9: 26346.829 | J9: 13641.994 | K9: 10460.46 | L9: 12546.167 | M9: 19894.543 | N9: 21649.848
A11: LTM Multiples
A12: EV Multiples
A13: EV/Revenue | B13: 2.2751479 | C13: 4.9698654 | D13: 4.9581256 | E13: 4.1700071 | F13: 4.1973985 | G13: 4.7257333 | H13: 4.7340337 | I13: 8.8118275 | J13: 7.3462005 | K13: 6.0363515 | L13: 7.631982 | M13: 7.6140266 | N13: 8.2502783
A14: EV/Gross Profit | B14: 4.1590554 | C14: 8.186601 | D14: 9.1632367 | E14: 7.2963878 | F14: 7.8416771 | G14: 9.363958 | H14: 7.8714644 | I14: 13.091626 | J14: 16.882952 | K14: 9.7286862 | L14: 15.392387 | M14: 14.219374 | N14: 11.365972
A15: EV/EBIT | B15: 4.8904082 | C15: 11.721378 | D15: 14.127607 | E15: 11.589113 | F15: 12.98824 | G15: 16.49757 | H15: 22.63902 | I15: 16.942282 | J15: 10.686751 | K15: 14.819644 | L15: 54.514775 | M15: 32.290562 | N15: 29.640654
A16: EV/EBITDA | B16: 4.4308105 | C16: 9.5469358 | D16: 9.433104 | E16: 5.9943172 | F16: 7.4151664 | G16: 12.257062 | H16: 17.567036 | I16: 12.66243 | J16: 10.424548 | K16: 14.050457 | L16: 44.920598 | M16: 36.107584 | N16: 30.075988
A17: EV/OCF | B17: -9.3620414 | C17: -3.417483 | D17: -8.9453822 | E17: -2.8538571 | F17: 13.476021 | G17: 11.027372 | H17: -4.7029891 | I17: -7.0495314 | J17: 35.09915 | K17: 2.3473628 | L17: -11.2393 | M17: -7.7453424 | N17: -13.398985
A18: EV/FCF | B18: -8.4469236 | C18: -2.3938929 | D18: -4.4369123 | E18: -2.7892269 | F18: 32.011134 | G18: 19.845625 | H18: -4.0252396 | I18: -6.9387551 | J18: 38.075624 | K18: 2.3866116 | L18: -10.934433 | M18: -7.6655489 | N18: -13.152216
A19: Equity Value Multiples
A20: P/Revenue | B20: 0.73438637 | C20: 0.74870019 | D20: 0.4703976 | E20: 0.40444296 | F20: 0.49100548 | G20: 1.0783 | H20: 1.4274345 | I20: 1.3317163 | J20: 1.6216995 | K20: 1.3695622 | L20: 1.9693907 | M20: 2.4072122 | N20: 2.2203947
A21: P/Gross Profit | B21: 1.3424857 | C21: 1.2332949 | D21: 0.86935364 | E21: 0.7076661 | F21: 0.9173078 | G21: 2.1366327 | H21: 2.3734517 | I21: 1.9785148 | J21: 3.7269706 | K21: 2.2073005 | L21: 3.9719202 | M21: 4.4955255 | N21: 3.0589205
A22: P/EBIT | B22: 1.5785563 | C22: 1.765802 | D22: 1.3403437 | E22: 1.1240114 | F22: 1.5193451 | G22: 3.7643534 | H22: 6.8262546 | I22: 2.5604579 | J22: 2.3591377 | K22: 3.3623662 | L22: 14.067236 | M22: 10.208821 | N22: 7.9771796
A23: P/EBITDA | B23: 1.4302045 | C23: 1.4382266 | D23: 0.89495705 | E23: 0.58138015 | F23: 0.86741521 | G23: 2.7967701 | H23: 5.2969191 | I23: 1.9136513 | J23: 2.3012553 | K23: 3.1878487 | L23: 11.591512 | M23: 11.415592 | N23: 8.0943408
A24: P/OCF | B24: -3.0219378 | C24: -0.51483692 | D24: -0.84868489 | E24: -0.27679147 | F24: 1.5764051 | G24: 2.5161842 | H24: -1.4180738 | I24: -1.0653835 | J24: 7.7482602 | K24: 0.53258322 | L24: -2.900239 | M24: -2.4487284 | N24: -3.6060646
A25: P/FCF | B25: -2.7265504 | C25: -0.36063513 | D25: -0.42094796 | E25: -0.27052308 | F25: 3.7446151 | G25: 4.5282999 | H25: -1.2137147 | I25: -1.0486421 | J25: 8.4053272 | K25: 0.54148822 | L25: -2.82157 | M25: -2.4235012 | N25: -3.5396517
A26: P/E | B26: 2.6046053 | C26: 10.827921 | D26: 7.914075 | E26: 6.629315 | F26: 8.531159 | G26: 11.204249 | H26: 9.4028842 | I26: 3.4730612 | J26: 3.2032852 | K26: 4.652075 | L26: 20.159967 | M26: 30.560862 | N26: 13.820713
A27: P/BV | B27: 0.52405915 | C27: 0.48723942 | D27: 0.34574335 | E27: 0.28823868 | F27: 0.32821785 | G27: 0.65039485 | H27: 1.3726121 | I27: 1.5502799 | J27: 1.1729842 | K27: 0.81626042 | L27: 1.2363583 | M27: 1.3901874 | N27: 1.6380847
A28: PEG Multiples
A29: PEG 1Y | B29: 0.050189564 | C29: 0.20864913 | D29: 0.15250064 | E29: 0.1277439 | F29: 0.16439157 | G29: 0.2159008 | H29: 0.18118932 | I29: 0.066924316 | J29: 0.061725854 | K29: 0.089643378 | L29: 0.38847343 | M29: 0.58889396 | N29: 0.26631889
A30: PEG 2Y | B30: 0.074786725 | C30: 0.31090498 | D30: 0.22723894 | E30: 0.19034929 | F30: 0.24495744 | G30: 0.32171058 | H30: 0.26998752 | I30: 0.099722932 | J30: 0.091976781 | K30: 0.13357627 | L30: 0.5788585 | M30: 0.87750216 | N30: 0.39683782
A32: NTM Multiples
A33: EV Multiples
A34: EV/EBIT | B34: 3.5664645 | C34: 9.2302109 | D34: 10.787295 | E34: 11.461875 | F34: 13.334831 | G34: 16.293711 | H34: 5.3005664 | I34: 21.264388 | J34: 19.95277 | K34: 12.750423 | L34: 19.001881 | M34: 22.320319 | N34: 27.807105
A35: EV/EBITDA | B35: 2.0018079 | C35: 5.1807916 | D35: 7.0369175 | E35: 6.9952276 | F35: 8.9386319 | G35: 9.4394526 | H35: 5.3307606 | I35: 20.605313 | J35: 18.951589 | K35: 11.282145 | L35: 18.002216 | M35: 20.810485 | N35: 25.926122
A36: EV/Revenue | B36: 1.1177481 | C36: 2.892795 | D36: 3.7761755 | E36: 3.4848814 | F36: 3.7551415 | G36: 4.3928267 | H36: 2.7013735 | I36: 9.0931632 | J36: 9.947081 | K36: 8.0110523 | L36: 9.3439512 | M36: 7.4655088 | N36: 9.3006818
A37: Equity Value Multiples
A38: P/E | B38: 6.7763935 | C38: 8.1850379 | D38: 5.9375987 | E38: 3.6803544 | F38: 4.6384209 | G38: 5.1095566 | H38: 2.1748809 | I38: 4.3516878 | J38: 5.9915847 | K38: 3.6727595 | L38: 6.2423932 | M38: 8.6117102 | N38: 9.1526431
A39: P/EBIT | B39: 1.1512055 | C39: 1.3905126 | D39: 1.0234347 | E39: 1.1116707 | F39: 1.5598889 | G39: 3.7178377 | H39: 1.5982589 | I39: 3.2136504 | J39: 4.4046437 | K39: 2.8928895 | L39: 4.9033302 | M39: 7.0566795 | N39: 7.4837171
A40: P/EBITDA | B40: 0.64615598 | C40: 0.7804758 | D40: 0.66762107 | E40: 0.67845701 | F40: 1.045628 | G40: 2.1538587 | H40: 1.6073633 | I40: 3.1140455 | J40: 4.1836296 | K40: 2.5597582 | L40: 4.6453721 | M40: 6.5793378 | N40: 6.9774889
A41: P/Revenue | B41: 0.36079366 | C41: 0.43579373 | D41: 0.35826117 | E41: 0.33799361 | F41: 0.4392709 | G41: 1.0023386 | H41: 0.81453451 | I41: 1.3742341 | J41: 2.1958529 | K41: 1.8175938 | L41: 2.4111549 | M41: 2.3602576 | N41: 2.5030895
A43: Forward Multiples
A44: 1Y Forward
A45: EV/EBIT | B45: 3.3605399 | C45: 8.6972665 | D45: 12.649046 | E45: 11.474471 | F45: 13.336162 | G45: 21.046669 | H45: 19.023177 | I45: 18.851684 | J45: 12.793465 | K45: 16.229672 | L45: 20.161506 | M45: 29.8456 | N45: 34.276664
A46: EV/EBITDA | B46: 3.0797538 | C46: 7.9705761 | D46: 11.592169 | E46: 7.4851858 | F46: 8.1391123 | G46: 11.186033 | H46: 7.9032219 | I46: 18.95907 | J46: 12.396941 | K46: 12.750318 | L46: 15.416919 | M46: 27.826725 | N46: 31.958055
...
